Traceback (most recent call last):
  File "/home/rasenk/.local/lib/python3.5/site-packages/pytg/sender.py", line 504, in _do_send
    answer = self.s.recv(1)
socket.timeout: timed out

During handling of the above exception, another exception occurred:

Traceback (most recent call last):
  File "macro.py", line 51, in work_with_message
    parse_text(msg['text'], msg['sender']['username'], msg['id'])
  File "macro.py", line 308, in parse_text
    send_msg('@', bot_username, 'ðŸ‘£Ð˜Ð´Ñ‚Ð¸ Ð´Ð°Ð»ÑŒÑˆÐµ')
  File "macro.py", line 317, in send_msg
    sender.send_msg(pref + to, message)
  File "/home/rasenk/.local/lib/python3.5/site-packages/pytg/sender.py", line 630, in command_alias
    return self.execute_function(command_name, *args, **kwargs)
  File "/home/rasenk/.local/lib/python3.5/site-packages/pytg/sender.py", line 318, in execute_function
    result = self._do_send(request, answer_timeout=result_timeout, retry_connect=retry_connect)
  File "/home/rasenk/.local/lib/python3.5/site-packages/pytg/sender.py", line 527, in _do_send
    raise NoResponse(command)
pytg.exceptions.NoResponse: [disable_preview] msg @WastelandWarsBot 'ðŸ‘£Ð˜Ð´Ñ‚Ð¸ Ð´Ð°Ð»ÑŒÑˆÐµ'


During handling of the above exception, another exception occurred:

Traceback (most recent call last):
  File "macro.py", line 321, in <module>
    receiver.message(work_with_message(receiver))
  File "/home/rasenk/.local/lib/python3.5/site-packages/pytg/utils.py", line 29, in start
    cr = func(*args, **kwargs)
  File "/home/rasenk/.local/lib/python3.5/site-packages/pytg/receiver.py", line 212, in message
    function.send(message)
  File "macro.py", line 53, in work_with_message
    if apikey is not None:
NameError: name 'apikey' is not defined

